Workbook

Sheet Supuestos
A1: Supuestos del modelo
A2: Editar solo las celdas azules sobre fondo ambar. Todo lo demas se recalcula.
A4: Parametro | B4: Valor | C4: Unidad | D4: Comentario
A5: Moneda | B5: USD | D5: Precios de lista publicos, sin impuestos
A6: Fecha de levantamiento | B6: 2026-08-16 | D6: Revalidar cada 6 meses: los precios SaaS cambian seguido
A7: Usuarios del cliente tipo | B7: 10 | C7: usuarios | D7: Base para normalizar precios por usuario contra tarifa plana
A8: Canales sociales del cliente tipo | B8: 5 | C8: canales | D8: Base para normalizar precios por canal
A9: Factor de posicionamiento | B9: 0.55 | C9: x mediana | D9: 0,55 = challenger. Subir a 0,7-0,9 si se compite por integracion y no por precio
A10: Descuento por pago anual | B10: 0.2 | C10: % | D10: Practica estandar del mercado

Sheet Mapa Competitivo
A1: KIMOS - Mapa competitivo y precio sugerido por aplicacion
A2: Montos en USD/mes para el cliente tipo. Precio sugerido = mediana del mercado x factor de posicionamiento.
A4: # | B4: App KIMOS | C4: Que hace | D4: Categoria de mercado | E4: Alternativas | F4: Target | G4: Min (PyME) | H4: Mediana (PyME) | I4: Max (todo el mercado) | J4: Precio sugerido KIMOS | K4: Por usuario | L4: Ahorro vs mediana | M4: A favor de KIMOS | N4: En contra de KIMOS | O4: Estrategia | P4: Confianza
A5: 1 | B5: Escritorio Kimos | C5: Control del escritorio, apertura de aplicaciones y chat entre agentes | D5: AI Workspace / agente de escritorio | E5: ChatGPT Business, Claude Team, M365 Copilot, Manus | F5: Toda la base instalada | G5: =MIN('Detalle Competencia'!G5:G9) -> 19 | H5: =MEDIAN('Detalle Competencia'!G5:G9) -> 210 | I5: =MAX('Detalle Competencia'!G5:G9) -> 250 | J5: =ROUND(H5*Supuestos!$B$9,0) -> 116 | K5: =ROUND(J5/Supuestos!$B$7,1) -> 11.6 | L5: =IF(H5=0,0,1-J5/H5) -> 0.44761905 | M5: Es el unico modulo que ningun competidor replica dentro de una suite: los demas venden el asistente aparte de las apps. Orquestar agentes sobre datos propios elimina el copy-paste entre herramientas. | N5: Compite contra OpenAI y Microsoft, que subsidian el precio. La calidad depende de modelos de terceros: si sube el costo del token, sube tu costo variable y no lo controlas. | O5: Ancla de la suite: incluir en todos los planes, nunca vender suelto | P5: 4/5
A6: 2 | B6: Agentes | C6: Agentes IA internos que ejecutan tareas del negocio | D6: Constructor de agentes IA | E6: Zapier, Lindy, Relevance AI, Notion Agents | F6: Equipos de operaciones | G6: =MIN('Detalle Competencia'!G10:G15) -> 19.99 | H6: =MEDIAN('Detalle Competencia'!G10:G15) -> 84.495 | I6: =MAX('Detalle Competencia'!G10:G15) -> 200 | J6: =ROUND(H6*Supuestos!$B$9,0) -> 46 | K6: =ROUND(J6/Supuestos!$B$7,1) -> 4.6 | L6: =IF(H6=0,0,1-J6/H6) -> 0.45558909 | M6: Los agentes ya viven donde estan los datos (CRM, archivos, productos). Zapier y Lindy tienen que conectarse por API a todo y pagan ese costo en latencia y fragilidad. | N6: Categoria con el ciclo de innovacion mas rapido del mercado y jugadores con capital ilimitado. El costo por credito es dificil de proyectar y erosiona margen si se subestima. | O6: Base fija baja + cobro por creditos de consumo | P6: 6/6
A7: 3 | B7: Agentes Web | C7: Chatbots y vendedores web (ej. vendedor_figit.ai) | D7: Chatbot / agente conversacional web | E7: Tidio, Intercom Fin, Chatbase, Crisp, ManyChat | F7: E-commerce y equipos de soporte | G7: =MIN('Detalle Competencia'!G16:G24) -> 14 | H7: =MEDIAN('Detalle Competencia'!G16:G24) -> 120 | I7: =MAX('Detalle Competencia'!G16:G24) -> 1320 | J7: =ROUND(H7*Supuestos!$B$9,0) -> 66 | K7: =ROUND(J7/Supuestos!$B$7,1) -> 6.6 | L7: =IF(H7=0,0,1-J7/H7) -> 0.45 | M7: El bot conoce el catalogo real (modulo Productos) y el pipeline (Prospeccion), no un PDF cargado a mano. Ese contexto es exactamente lo que Chatbase no puede dar. | N7: Intercom domina el segmento medio-alto con una marca enorme y Tidio el bajo con precio agresivo. Sin volumen de conversaciones, el modelo por resolucion de Intercom sale mas barato. | O7: Modulo premium: alto valor percibido y ROI demostrable | P7: 9/9
A8: 4 | B8: Archivos | C8: Gestor documental de la organizacion | D8: Almacenamiento y gestion documental | E8: Google Workspace, Dropbox Business, Box, Egnyte | F8: Toda la base instalada | G8: =MIN('Detalle Competencia'!G25:G31) -> 70 | H8: =MEDIAN('Detalle Competencia'!G25:G31) -> 200 | I8: =MAX('Detalle Competencia'!G25:G31) -> 240 | J8: =ROUND(H8*Supuestos!$B$9,0) -> 110 | K8: =ROUND(J8/Supuestos!$B$7,1) -> 11 | L8: =IF(H8=0,0,1-J8/H8) -> 0.45 | M8: Los archivos quedan junto a las tareas, productos y clientes que los originan, sin una capa de integracion de por medio. | N8: Es la categoria mas comoditizada que existe y compite contra almacenamiento a escala de Google. Nadie cambia de proveedor de archivos por si solo: solo migra si migra todo. | O8: Commodity: incluir en el core, jamas vender suelto | P8: 7/7
A9: 5 | B9: Conocimiento | C9: Base de conocimiento corporativa | D9: Knowledge base / wiki con IA | E9: Confluence, Guru, Slite, Notion, Document360 | F9: Equipos de 10+ personas | G9: =MIN('Detalle Competencia'!G32:G36) -> 54.2 | H9: =MEDIAN('Detalle Competencia'!G32:G36) -> 199 | I9: =MAX('Detalle Competencia'!G32:G36) -> 250 | J9: =ROUND(H9*Supuestos!$B$9,0) -> 109 | K9: =ROUND(J9/Supuestos!$B$7,1) -> 10.9 | L9: =IF(H9=0,0,1-J9/H9) -> 0.45226131 | M9: La busqueda alimenta directamente a los agentes: el conocimiento no es un repositorio muerto sino el contexto que consume el resto de la suite. | N9: Notion y Confluence tienen ecosistemas de plantillas y comunidades que tomaron una decada construir. Migrar documentacion es doloroso y frena la venta. | O9: Incluir en el core; diferenciar con busqueda IA nativa | P9: 5/5
A10: 6 | B10: Equipos | C10: Colaboracion y comunicacion por equipo | D10: Colaboracion / chat de equipo | E10: Slack, Microsoft Teams, Google Chat | F10: Toda la base instalada | G10: =MIN('Detalle Competencia'!G37:G41) -> 40 | H10: =MEDIAN('Detalle Competencia'!G37:G41) -> 72.5 | I10: =MAX('Detalle Competencia'!G37:G41) -> 125 | J10: =ROUND(H10*Supuestos!$B$9,0) -> 40 | K10: =ROUND(J10/Supuestos!$B$7,1) -> 4 | L10: =IF(H10=0,0,1-J10/H10) -> 0.44827586 | M10: Conversacion pegada al trabajo, sin saltar entre Slack y el gestor de tareas. | N10: Es la categoria mas dificil de desplazar del mercado: el chat tiene efecto de red y Teams viene gratis con Microsoft 365. Recomendacion honesta: no pelear aqui, integrarse. | O10: Commodity: incluir en el core | P10: 5/5
A11: 7 | B11: Kanban | C11: Tableros de tareas y flujos de trabajo | D11: Gestion de tareas Kanban | E11: Trello, ClickUp, Monday.com, Asana, Jira | F11: Todos los equipos | G11: =MIN('Detalle Competencia'!G42:G50) -> 50 | H11: =MEDIAN('Detalle Competencia'!G42:G50) -> 120 | I11: =MAX('Detalle Competencia'!G42:G50) -> 249.9 | J11: =ROUND(H11*Supuestos!$B$9,0) -> 66 | K11: =ROUND(J11/Supuestos!$B$7,1) -> 6.6 | L11: =IF(H11=0,0,1-J11/H11) -> 0.45 | M11: Funcionalidad de paridad razonable y es el modulo mas facil de adoptar sin capacitacion. Buen caballo de Troya para entrar a la cuenta. | N11: Mercado saturado con Trello a USD 5 y ClickUp a USD 7. Cero disposicion a pagar mas que el lider, y el costo de cambio para el cliente es bajisimo. | O11: Modulo de entrada con precio agresivo: sirve para adquirir, no para monetizar | P11: 9/9
A12: 8 | B12: Planificacion (Gantt) | C12: Planificacion de proyectos en diagrama de Gantt | D12: Planificacion de proyectos / Gantt | E12: Smartsheet, Wrike, MS Project, TeamGantt, Instagantt | F12: PMOs y consultoras | G12: =MIN('Detalle Competencia'!G51:G58) -> 19 | H12: =MEDIAN('Detalle Competencia'!G51:G58) -> 100 | I12: =MAX('Detalle Competencia'!G51:G58) -> 300 | J12: =ROUND(H12*Supuestos!$B$9,0) -> 55 | K12: =ROUND(J12/Supuestos!$B$7,1) -> 5.5 | L12: =IF(H12=0,0,1-J12/H12) -> 0.45 | M12: Vendido junto a Kanban da una propuesta que Trello no tiene y Smartsheet cobra a USD 19. | N12: MS Project es el estandar de facto en organizaciones grandes por inercia. Gantt suelto es un producto de nicho: casi nadie lo compra aislado. | O12: Vender empaquetado con Kanban como modulo unico de gestion de proyectos | P12: 8/8
A13: 9 | B13: Notas de Equipo | C13: Notas colaborativas y seguimiento de modificaciones | D13: Notas colaborativas / docs | E13: Notion, Coda, Evernote Teams, Slite | F13: Toda la base instalada | G13: =MIN('Detalle Competencia'!G59:G63) -> 80 | H13: =MEDIAN('Detalle Competencia'!G59:G63) -> 120 | I13: =MAX('Detalle Competencia'!G59:G63) -> 360 | J13: =ROUND(H13*Supuestos!$B$9,0) -> 66 | K13: =ROUND(J13/Supuestos!$B$7,1) -> 6.6 | L13: =IF(H13=0,0,1-J13/H13) -> 0.45 | M13: Las notas se vinculan a tareas y clientes reales en vez de vivir en un documento aislado. | N13: Notion define la categoria y tiene una comunidad gigantesca de plantillas. Competir de frente en features de documento es una batalla perdida. | O13: Incluir en el core | P13: 5/5
A14: 10 | B14: HTML Panel / Dashboards | C14: Paneles HTML personalizados (BSC, analisis estrategico) | D14: Dashboards y paneles embebidos | E14: Retool, Power BI, Tableau, Geckoboard | F14: Gerencia y direccion | G14: =MIN('Detalle Competencia'!G64:G70) -> 100 | H14: =MEDIAN('Detalle Competencia'!G64:G70) -> 240 | I14: =MAX('Detalle Competencia'!G64:G70) -> 750 | J14: =ROUND(H14*Supuestos!$B$9,0) -> 132 | K14: =ROUND(J14/Supuestos!$B$7,1) -> 13.2 | L14: =IF(H14=0,0,1-J14/H14) -> 0.45 | M14: Los datos ya estan dentro de la suite: no hay ETL ni conectores que mantener. Power BI necesita una capa de integracion completa para llegar a lo mismo. | N14: Power BI a USD 14 con el peso de Microsoft detras es dificil de superar en percepcion. Requiere perfiles tecnicos para armar los paneles y eso encarece el onboarding. | O14: Diferenciador tecnico: modulo premium con servicios de implementacion | P14: 7/7
A15: 11 | B15: FossFLOW (BPM) | C15: Gestion y automatizacion de procesos de negocio, con supervision por etapa | D15: BPM / automatizacion de procesos | E15: Pipefy, Kissflow, Nintex, Process Street, monday.com | F15: Empresas con procesos regulados | G15: =MIN('Detalle Competencia'!G71:G74) -> 90 | H15: =MEDIAN('Detalle Competencia'!G71:G74) -> 99.5 | I15: =MAX('Detalle Competencia'!G71:G76) -> 2500 | J15: =ROUND(H15*Supuestos!$B$9,0) -> 55 | K15: =ROUND(J15/Supuestos!$B$7,1) -> 5.5 | L15: =IF(H15=0,0,1-J15/H15) -> 0.44723618 | M15: Categoria con precios altos y competidores caros o pesados: Kissflow parte en USD 2.500/mes de plataforma y Nintex en USD 1.405. Hay mucho espacio para entrar por debajo con algo usable. | N15: Es el modulo mas dificil de construir bien: motor de reglas, versionado, auditoria y cumplimiento. Vender BPM exige consultoria y ciclos de venta largos. | O15: Modulo premium: es donde el ticket sube sin resistencia | P15: 5/6
A16: 12 | B16: Digitai (automatizacion IA) | C16: Gestion y automatizacion de tareas de IA y procesamiento de datos | D16: Automatizacion IA / orquestacion de datos | E16: Dify, Flowise, n8n, Relevance AI | F16: Equipos tecnicos | G16: =MIN('Detalle Competencia'!G77:G82) -> 24 | H16: =MEDIAN('Detalle Competencia'!G77:G82) -> 62 | I16: =MAX('Detalle Competencia'!G77:G82) -> 199 | J16: =ROUND(H16*Supuestos!$B$9,0) -> 34 | K16: =ROUND(J16/Supuestos!$B$7,1) -> 3.4 | L16: =IF(H16=0,0,1-J16/H16) -> 0.4516129 | M16: Complementa a los Agentes con el pipeline de datos que los alimenta. Precios de referencia razonables (Dify USD 59, n8n USD 24) dejan margen. | N16: Se solapa fuerte con el modulo Agentes: dos productos que el cliente percibe como uno. Ademas compite contra open source gratuito y autohospedable, que es un techo de precio duro. | O16: Cobro por consumo; evaluar fusionarlo con Agentes | P16: 5/6
A17: 13 | B17: Formularios de Contacto | C17: Administracion de formularios de contacto | D17: Formularios y captura de leads | E17: Typeform, Jotform, Tally, Fillout | F17: Marketing y ventas | G17: =MIN('Detalle Competencia'!G83:G90) -> 24 | H17: =MEDIAN('Detalle Competencia'!G83:G90) -> 49.5 | I17: =MAX('Detalle Competencia'!G83:G90) -> 129 | J17: =ROUND(H17*Supuestos!$B$9,0) -> 27 | K17: =ROUND(J17/Supuestos!$B$7,1) -> 2.7 | L17: =IF(H17=0,0,1-J17/H17) -> 0.45454545 | M17: El lead entra directo al CRM sin Zapier de por medio. Typeform cobra USD 29 solo por 100 respuestas al mes. | N17: Tally regala respuestas ilimitadas en su plan free: el piso de precio de la categoria tiende a cero. No es un modulo del que se pueda vivir. | O17: Gancho de entrada freemium con limite de respuestas | P17: 8/8
A18: 14 | B18: Prospeccion Comercial | C18: Gestion y seguimiento de prospeccion de clientes | D18: CRM / prospeccion de ventas | E18: Pipedrive, HubSpot, Apollo.io, Salesforce | F18: Equipos comerciales | G18: =MIN('Detalle Competencia'!G91:G102) -> 140 | H18: =MEDIAN('Detalle Competencia'!G91:G102) -> 540 | I18: =MAX('Detalle Competencia'!G91:G102) -> 1750 | J18: =ROUND(H18*Supuestos!$B$9,0) -> 297 | K18: =ROUND(J18/Supuestos!$B$7,1) -> 29.7 | L18: =IF(H18=0,0,1-J18/H18) -> 0.45 | M18: Es donde el cliente ya acepta pagar USD 39-100 por asiento. Integrado con Agentes Web y Formularios cierra el ciclo completo de lead a venta, algo que Pipedrive solo hace comprando add-ons. | N18: Categoria con costo de cambio altisimo: nadie migra su CRM a la ligera. Salesforce y HubSpot tienen ecosistemas de partners que KIMOS no puede igualar en el corto plazo. | O18: El modulo con mayor disposicion a pagar de toda la suite | P18: 12/12
A19: 15 | B19: Social Planner | C19: Planificacion de contenido en redes sociales | D19: Gestion y programacion de redes | E19: Buffer, Hootsuite, Metricool, Later, Sprout Social | F19: Marketing y agencias | G19: =MIN('Detalle Competencia'!G103:G109) -> 18 | H19: =MEDIAN('Detalle Competencia'!G103:G109) -> 50 | I19: =MAX('Detalle Competencia'!G103:G109) -> 2490 | J19: =ROUND(H19*Supuestos!$B$9,0) -> 28 | K19: =ROUND(J19/Supuestos!$B$7,1) -> 2.8 | L19: =IF(H19=0,0,1-J19/H19) -> 0.44 | M19: Junto a Kreative Studio cubre crear y publicar en un solo lugar; Buffer y Hootsuite solo publican. | N19: Depende de APIs de terceros (Meta, TikTok, LinkedIn) que cambian sin aviso y obligan a mantenimiento constante. Metricool a USD 18 fija un techo bajo. | O19: Cobrar por canal conectado, nunca por usuario | P19: 7/7
A20: 16 | B20: Kreative Studio | C20: Creacion de contenido visual: posts, banners, logos y material grafico | D20: Diseno grafico / contenido visual | E20: Canva, Adobe Express, Figma, VistaCreate | F20: Marketing y disenadores | G20: =MIN('Detalle Competencia'!G110:G113) -> 79.9 | H20: =MEDIAN('Detalle Competencia'!G110:G113) -> 110 | I20: =MAX('Detalle Competencia'!G110:G113) -> 130 | J20: =ROUND(H20*Supuestos!$B$9,0) -> 61 | K20: =ROUND(J20/Supuestos!$B$7,1) -> 6.1 | L20: =IF(H20=0,0,1-J20/H20) -> 0.44545455 | M20: El diseno conectado al catalogo de productos y al calendario de publicacion es un flujo que Canva no tiene cerrado. | N20: Canva tiene 200+ millones de usuarios, una biblioteca de plantillas imposible de replicar y cobra USD 10. Competir en features de diseno puro no es realista. | O20: Vender junto a Social Planner como paquete de marketing | P20: 3/4
A21: 17 | B21: Kimos FunPlai (gamificacion) | C21: Gamificacion y experiencias interactivas: juegos, concursos y actividades ludicas | D21: Gamificacion y engagement | E21: Kahoot!, Spinify, Mentimeter, TalentLMS, Gametize | F21: RRHH, marketing y eventos | G21: =MIN('Detalle Competencia'!G114:G119) -> 29 | H21: =MEDIAN('Detalle Competencia'!G114:G119) -> 104.5 | I21: =MAX('Detalle Competencia'!G114:G119) -> 400 | J21: =ROUND(H21*Supuestos!$B$9,0) -> 57 | K21: =ROUND(J21/Supuestos!$B$7,1) -> 5.7 | L21: =IF(H21=0,0,1-J21/H21) -> 0.45454545 | M21: Categoria fragmentada y sin lider claro en el mundo hispano. Conectado a Equipos y Eventos permite gamificar procesos internos reales, no solo trivias sueltas. | N21: Uso episodico: la gente lo usa para una campana y lo abandona, lo que produce churn alto si se cobra mensual. Kahoot domina el reconocimiento de marca en lo educativo. | O21: Add-on por campana o por evento, no suscripcion mensual fija | P21: 4/6
A22: 18 | B22: ProductLab | C22: Gestion de producto, investigacion y desarrollo | D22: Product management / roadmap | E22: Productboard, Aha!, Airfocus, Jira Product Discovery | F22: Empresas con equipo de producto | G22: =MIN('Detalle Competencia'!G120:G126) -> 100 | H22: =MEDIAN('Detalle Competencia'!G120:G126) -> 390 | I22: =MAX('Detalle Competencia'!G120:G126) -> 800 | J22: =ROUND(H22*Supuestos!$B$9,0) -> 215 | K22: =ROUND(J22/Supuestos!$B$7,1) -> 21.5 | L22: =IF(H22=0,0,1-J22/H22) -> 0.44871795 | M22: Precios de referencia altos (Productboard Pro USD 80, Aha! USD 59) y competidores percibidos como caros y complejos. | N22: Nicho estrecho: solo lo compran empresas con equipo de producto formal. En Latinoamerica ese perfil es escaso y alarga el ciclo de venta. | O22: Nicho de ticket alto: pocos asientos, precio elevado por asiento | P22: 7/7
A23: 19 | B23: Productos (PIM) | C23: Gestion de catalogos de productos | D23: PIM / catalogo de productos | E23: Plytix, Akeneo, Salsify, Sales Layer | F23: Retail, distribucion y manufactura | G23: =MIN('Detalle Competencia'!G127:G129) -> 300 | H23: =MEDIAN('Detalle Competencia'!G127:G129) -> 499 | I23: =MAX('Detalle Competencia'!G127:G131) -> 6250 | J23: =ROUND(H23*Supuestos!$B$9,0) -> 274 | K23: =ROUND(J23/Supuestos!$B$7,1) -> 27.4 | L23: =IF(H23=0,0,1-J23/H23) -> 0.4509018 | M23: La brecha de precio es enorme: Plytix cobra USD 499 y Akeneo parte en USD 45.000 al ano. Integrado con Tienda y Vitrina, KIMOS cubre el ciclo entero que Plytix vende como add-ons de USD 300 cada uno. | N23: PIM es intensivo en calidad de datos y migracion: el proyecto se juega en la implementacion, no en el software. Exige un equipo de soporte tecnico solido. | O23: Tarifa plana por volumen de SKU con asientos ilimitados | P23: 4/5
A24: 20 | B24: Tienda (e-commerce) | C24: Tienda en linea | D24: E-commerce / storefront | E24: Shopify, BigCommerce, Wix, WooCommerce | F24: Retail y PyMEs con venta online | G24: =MIN('Detalle Competencia'!G132:G138) -> 17 | H24: =MEDIAN('Detalle Competencia'!G132:G138) -> 105 | I24: =MAX('Detalle Competencia'!G132:G138) -> 399 | J24: =ROUND(H24*Supuestos!$B$9,0) -> 58 | K24: =ROUND(J24/Supuestos!$B$7,1) -> 5.8 | L24: =IF(H24=0,0,1-J24/H24) -> 0.44761905 | M24: Con PIM y Vitrina integrados, la tienda se alimenta sola desde el catalogo maestro. | N24: Shopify es un monopolio blando con un app store de miles de integraciones. Sin ese ecosistema, la tienda de KIMOS sera funcionalmente mas pobre por varios anos. Recomendacion honesta: integrarse con Shopify antes que competirle. | O24: Tarifa plana; evaluar comision sobre GMV solo en tiers bajos | P24: 7/7
A25: 21 | B25: Vitrina (catalogo digital) | C25: Vitrina publica de productos y marca | D25: Catalogo digital / brand portal | E25: Linktree, Flipsnack, Plytix Brand Portals | F25: Retail y marcas | G25: =MIN('Detalle Competencia'!G139:G143) -> 9 | H25: =MEDIAN('Detalle Competencia'!G139:G143) -> 24 | I25: =MAX('Detalle Competencia'!G139:G143) -> 300 | J25: =ROUND(H25*Supuestos!$B$9,0) -> 13 | K25: =ROUND(J25/Supuestos!$B$7,1) -> 1.3 | L25: =IF(H25=0,0,1-J25/H25) -> 0.45833333 | M25: Plytix cobra USD 300 por el mismo add-on. Como complemento del PIM es margen casi puro. | N25: Es una feature, no un producto: nadie contrata una suite por su vitrina. Vendida suelta compite con Linktree a USD 9. | O25: Add-on economico sobre Productos o Tienda | P25: 1/5
A26: 22 | B26: KIMOS Cashflow | C26: Gestion del flujo de caja | D26: Gestion y proyeccion de flujo de caja | E26: Float, Fathom, Agicap, Dryrun | F26: Gerencia financiera y PyMEs | G26: =MIN('Detalle Competencia'!G144:G149) -> 49 | H26: =MEDIAN('Detalle Competencia'!G144:G149) -> 139.5 | I26: =MAX('Detalle Competencia'!G144:G149) -> 260 | J26: =ROUND(H26*Supuestos!$B$9,0) -> 77 | K26: =ROUND(J26/Supuestos!$B$7,1) -> 7.7 | L26: =IF(H26=0,0,1-J26/H26) -> 0.44802867 | M26: Categoria con precios sanos (Float USD 49-199, Fathom hasta USD 260) y competidores extranjeros con poca adaptacion tributaria local. | N26: Exige integracion con bancos y ERPs locales para ser util de verdad, y eso es trabajo pais por pais. Sin conciliacion automatica queda en una planilla bonita. | O26: Tarifa plana por empresa, nunca por usuario | P26: 5/6
A27: 23 | B27: Gestion de Eventos | C27: Gestion de eventos corporativos (Desayuno Ciberseguridad 2026) | D27: Gestion de eventos | E27: Luma, Eventbrite, Bizzabo, Cvent | F27: Marketing corporativo | G27: =MIN('Detalle Competencia'!G150:G152) -> 15 | H27: =MEDIAN('Detalle Competencia'!G150:G152) -> 59 | I27: =MAX('Detalle Competencia'!G150:G154) -> 4990 | J27: =ROUND(H27*Supuestos!$B$9,0) -> 32 | K27: =ROUND(J27/Supuestos!$B$7,1) -> 3.2 | L27: =IF(H27=0,0,1-J27/H27) -> 0.45762712 | M27: El evento se conecta al CRM y a los formularios: los asistentes se vuelven leads automaticamente. Bizzabo cobra USD 499 por usuario para hacer eso mismo. | N27: Uso estacional con churn natural. Luma es gratis y muy bueno para eventos chicos, lo que aplasta el precio en el segmento de entrada. | O27: Cobrar por evento o campana, no como suscripcion mensual | P27: 3/5
A28: 24 | B28: Integraciones | C28: Conexion con sistemas externos | D28: iPaaS / automatizacion | E28: Zapier, Make, n8n | F28: Toda la base instalada | G28: =MIN('Detalle Competencia'!G155:G158) -> 9 | H28: =MEDIAN('Detalle Competencia'!G155:G158) -> 21.995 | I28: =MAX('Detalle Competencia'!G155:G158) -> 69 | J28: =ROUND(H28*Supuestos!$B$9,0) -> 12 | K28: =ROUND(J28/Supuestos!$B$7,1) -> 1.2 | L28: =IF(H28=0,0,1-J28/H28) -> 0.45442146 | M28: Al vivir dentro de la suite evita el costo de conectar cada app entre si, que es justamente el problema que Zapier existe para resolver. | N28: Make cobra USD 9 por 10.000 operaciones y n8n es gratis autohospedado. El techo de precio es muy bajo y el valor solo aparece hacia afuera de la suite. | O28: Incluir en el core y cobrar por volumen de ejecuciones | P28: 4/4
B30: Modulos de plataforma (Apariencia, Configuracion, Seguridad, Usuarios): parte del core, sin precio de mercado comparable.

Sheet Detalle Competencia
A1: Detalle de precios de la competencia
A2: Precio de lista publicado. La columna G normaliza todo al cliente tipo para comparar manzanas con manzanas.
A4: App KIMOS | B4: Competidor | C4: Plan | D4: Precio (USD/mes) | E4: Unidad de cobro | F4: Multiplicador | G4: Costo mensual cliente tipo | H4: Segmento | I4: Notas | J4: Fuente | K4: Confianza
A5: Escritorio Kimos | B5: ChatGPT Business | C5: Business | D5: 20 | E5: Por usuario | F5: =IF(E5="Por usuario",Supuestos!$B$7,IF(E5="Por canal",Supuestos!$B$8,1)) -> 10 | G5: =D5*F5 -> 200 | H5: PyME / Empresa | I5: Enterprise ~USD 60/asiento | J5: coworker.ai/blog/chatgpt-enterprise-pricing | K5: Verificado
A6: Escritorio Kimos | B6: ChatGPT Team | C6: Team | D6: 25 | E6: Por usuario | F6: =IF(E6="Por usuario",Supuestos!$B$7,IF(E6="Por canal",Supuestos!$B$8,1)) -> 10 | G6: =D6*F6 -> 250 | H6: PyME / Empresa | J6: coworker.ai/blog/chatgpt-enterprise-pricing | K6: Verificado
A7: Escritorio Kimos | B7: Claude Team | C7: Team | D7: 25 | E7: Por usuario | F7: =IF(E7="Por usuario",Supuestos!$B$7,IF(E7="Por canal",Supuestos!$B$8,1)) -> 10 | G7: =D7*F7 -> 250 | H7: PyME / Empresa | I7: Minimo 5 asientos | J7: fusioncomputing.ca/copilot-vs-chatgpt-vs-claude | K7: Verificado
A8: Escritorio Kimos | B8: Microsoft 365 Copilot | C8: Business | D8: 21 | E8: Por usuario | F8: =IF(E8="Por usuario",Supuestos!$B$7,IF(E8="Por canal",Supuestos!$B$8,1)) -> 10 | G8: =D8*F8 -> 210 | H8: PyME / Empresa | I8: USD 18 promocional hasta sep-2026; exige licencia M365 | J8: geotoolbox.ai/blog/copilot-pricing | K8: Verificado
A9: Escritorio Kimos | B9: Manus | C9: Starter | D9: 19 | E9: Plano | F9: =IF(E9="Por usuario",Supuestos!$B$7,IF(E9="Por canal",Supuestos!$B$8,1)) -> 1 | G9: =D9*F9 -> 19 | H9: PyME / Empresa | I9: Agente autonomo por creditos | J9: manus.im/pricing | K9: Estimado
A10: Agentes | B10: Zapier | C10: Professional | D10: 19.99 | E10: Plano | F10: =IF(E10="Por usuario",Supuestos!$B$7,IF(E10="Por canal",Supuestos!$B$8,1)) -> 1 | G10: =D10*F10 -> 19.99 | H10: PyME / Empresa | I10: Free con 100 tareas/mes | J10: lindy.ai/blog/zapier-pricing | K10: Verificado
A11: Agentes | B11: Zapier | C11: Team | D11: 69 | E11: Plano | F11: =IF(E11="Por usuario",Supuestos!$B$7,IF(E11="Por canal",Supuestos!$B$8,1)) -> 1 | G11: =D11*F11 -> 69 | H11: PyME / Empresa | I11: Usuarios ilimitados | J11: lindy.ai/blog/zapier-pricing | K11: Verificado
A12: Agentes | B12: Lindy | C12: Plus | D12: 49.99 | E12: Plano | F12: =IF(E12="Por usuario",Supuestos!$B$7,IF(E12="Por canal",Supuestos!$B$8,1)) -> 1 | G12: =D12*F12 -> 49.99 | H12: PyME / Empresa | I12: Cobro por creditos, sobreconsumo al doble | J12: coworker.ai/blog/lindy-ai-pricing | K12: Verificado
A13: Agentes | B13: Lindy | C13: Pro | D13: 99.99 | E13: Plano | F13: =IF(E13="Por usuario",Supuestos!$B$7,IF(E13="Por canal",Supuestos!$B$8,1)) -> 1 | G13: =D13*F13 -> 99.99 | H13: PyME / Empresa | J13: coworker.ai/blog/lindy-ai-pricing | K13: Verificado
A14: Agentes | B14: Lindy | C14: Max | D14: 199.99 | E14: Plano | F14: =IF(E14="Por usuario",Supuestos!$B$7,IF(E14="Por canal",Supuestos!$B$8,1)) -> 1 | G14: =D14*F14 -> 199.99 | H14: PyME / Empresa | J14: coworker.ai/blog/lindy-ai-pricing | K14: Verificado
A15: Agentes | B15: Notion | C15: Business (Agents) | D15: 20 | E15: Por usuario | F15: =IF(E15="Por usuario",Supuestos!$B$7,IF(E15="Por canal",Supuestos!$B$8,1)) -> 10 | G15: =D15*F15 -> 200 | H15: PyME / Empresa | I15: Agentes custom: USD 10 / 1.000 creditos | J15: notion.com/pricing | K15: Verificado
A16: Agentes Web | B16: Tidio | C16: Starter | D16: 24.17 | E16: Plano | F16: =IF(E16="Por usuario",Supuestos!$B$7,IF(E16="Por canal",Supuestos!$B$8,1)) -> 1 | G16: =D16*F16 -> 24.17 | H16: PyME / Empresa | I16: Pago anual | J16: tidio.com/pricing | K16: Verificado
A17: Agentes Web | B17: Tidio | C17: Growth | D17: 49.17 | E17: Plano | F17: =IF(E17="Por usuario",Supuestos!$B$7,IF(E17="Por canal",Supuestos!$B$8,1)) -> 1 | G17: =D17*F17 -> 49.17 | H17: PyME / Empresa | I17: Pago anual | J17: tidio.com/pricing | K17: Verificado
A18: Agentes Web | B18: Tidio | C18: Plus | D18: 300 | E18: Plano | F18: =IF(E18="Por usuario",Supuestos!$B$7,IF(E18="Por canal",Supuestos!$B$8,1)) -> 1 | G18: =D18*F18 -> 300 | H18: PyME / Empresa | I18: Pago anual | J18: tidio.com/pricing | K18: Verificado
A19: Agentes Web | B19: Intercom | C19: Essential | D19: 29 | E19: Por usuario | F19: =IF(E19="Por usuario",Supuestos!$B$7,IF(E19="Por canal",Supuestos!$B$8,1)) -> 10 | G19: =D19*F19 -> 290 | H19: PyME / Empresa | I19: Fin AI: USD 0,99 por resolucion | J19: flowgent.ai/blog/intercom-chatbot-pricing-guide-and-comparison | K19: Verificado
A20: Agentes Web | B20: Intercom | C20: Advanced | D20: 85 | E20: Por usuario | F20: =IF(E20="Por usuario",Supuestos!$B$7,IF(E20="Por canal",Supuestos!$B$8,1)) -> 10 | G20: =D20*F20 -> 850 | H20: PyME / Empresa | I20: Incluye 20 asientos Lite | J20: flowgent.ai/blog/intercom-chatbot-pricing-guide-and-comparison | K20: Verificado
A21: Agentes Web | B21: Intercom | C21: Expert | D21: 132 | E21: Por usuario | F21: =IF(E21="Por usuario",Supuestos!$B$7,IF(E21="Por canal",Supuestos!$B$8,1)) -> 10 | G21: =D21*F21 -> 1320 | H21: PyME / Empresa | J21: flowgent.ai/blog/intercom-chatbot-pricing-guide-and-comparison | K21: Verificado
A22: Agentes Web | B22: Chatbase | C22: Standard | D22: 120 | E22: Plano | F22: =IF(E22="Por usuario",Supuestos!$B$7,IF(E22="Por canal",Supuestos!$B$8,1)) -> 1 | G22: =D22*F22 -> 120 | H22: PyME / Empresa | I22: 4.000 creditos; sobrecosto USD 40/1.000 | J22: blog.fastbots.ai/ai-chatbot-pricing-comparison | K22: Verificado
A23: Agentes Web | B23: Crisp | C23: Essentials | D23: 103 | E23: Plano | F23: =IF(E23="Por usuario",Supuestos!$B$7,IF(E23="Por canal",Supuestos!$B$8,1)) -> 1 | G23: =D23*F23 -> 103 | H23: PyME / Empresa | I23: EUR 95 convertidos | J23: featurebase.app/blog/crisp-vs-intercom | K23: Verificado
A24: Agentes Web | B24: ManyChat | C24: Pro | D24: 14 | E24: Plano | F24: =IF(E24="Por usuario",Supuestos!$B$7,IF(E24="Por canal",Supuestos!$B$8,1)) -> 1 | G24: =D24*F24 -> 14 | H24: PyME / Empresa | I24: 250 contactos activos; USD 139 con 25.000 | J24: elfsight.com/blog/how-much-does-a-chatbot-cost | K24: Verificado
A25: Archivos | B25: Google Workspace | C25: Business Starter | D25: 7 | E25: Por usuario | F25: =IF(E25="Por usuario",Supuestos!$B$7,IF(E25="Por canal",Supuestos!$B$8,1)) -> 10 | G25: =D25*F25 -> 70 | H25: PyME / Empresa | I25: 30 GB por usuario | J25: workspace.google.com/pricing | K25: Verificado
A26: Archivos | B26: Google Workspace | C26: Business Standard | D26: 14 | E26: Por usuario | F26: =IF(E26="Por usuario",Supuestos!$B$7,IF(E26="Por canal",Supuestos!$B$8,1)) -> 10 | G26: =D26*F26 -> 140 | H26: PyME / Empresa | I26: 2 TB por usuario | J26: workspace.google.com/pricing | K26: Verificado
A27: Archivos | B27: Google Workspace | C27: Business Plus | D27: 22 | E27: Por usuario | F27: =IF(E27="Por usuario",Supuestos!$B$7,IF(E27="Por canal",Supuestos!$B$8,1)) -> 10 | G27: =D27*F27 -> 220 | H27: PyME / Empresa | I27: 5 TB por usuario | J27: workspace.google.com/pricing | K27: Verificado
A28: Archivos | B28: Dropbox Business | C28: Standard | D28: 15 | E28: Por usuario | F28: =IF(E28="Por usuario",Supuestos!$B$7,IF(E28="Por canal",Supuestos!$B$8,1)) -> 10 | G28: =D28*F28 -> 150 | H28: PyME / Empresa | I28: 5 TB compartidos | J28: costbench.com/software/document-management/dropbox-business | K28: Verificado
A29: Archivos | B29: Dropbox Business | C29: Advanced | D29: 24 | E29: Por usuario | F29: =IF(E29="Por usuario",Supuestos!$B$7,IF(E29="Por canal",Supuestos!$B$8,1)) -> 10 | G29: =D29*F29 -> 240 | H29: PyME / Empresa | I29: Almacenamiento ilimitado | J29: costbench.com/software/document-management/dropbox-business | K29: Verificado
A30: Archivos | B30: Egnyte | C30: Business | D30: 22 | E30: Por usuario | F30: =IF(E30="Por usuario",Supuestos!$B$7,IF(E30="Por canal",Supuestos!$B$8,1)) -> 10 | G30: =D30*F30 -> 220 | H30: PyME / Empresa | J30: egnyte.com/pricing | K30: Verificado
A31: Archivos | B31: Box | C31: Business | D31: 20 | E31: Por usuario | F31: =IF(E31="Por usuario",Supuestos!$B$7,IF(E31="Por canal",Supuestos!$B$8,1)) -> 10 | G31: =D31*F31 -> 200 | H31: PyME / Empresa | I31: USD 25 con pago mensual | J31: bestcloudstorageguide.com/blog/box-pricing | K31: Verificado
A32: Conocimiento | B32: Confluence | C32: Standard | D32: 5.42 | E32: Por usuario | F32: =IF(E32="Por usuario",Supuestos!$B$7,IF(E32="Por canal",Supuestos!$B$8,1)) -> 10 | G32: =D32*F32 -> 54.2 | H32: PyME / Empresa | J32: docsie.io/blog/articles/confluence-vs-document360-pricing-comparison-2026 | K32: Verificado
A33: Conocimiento | B33: Guru | C33: All-in-one | D33: 25 | E33: Por usuario | F33: =IF(E33="Por usuario",Supuestos!$B$7,IF(E33="Por canal",Supuestos!$B$8,1)) -> 10 | G33: =D33*F33 -> 250 | H33: PyME / Empresa | I33: Minimo 10 asientos | J33: usecarly.com/blog/guru-alternatives | K33: Verificado
A34: Conocimiento | B34: Slite | C34: Standard | D34: 8 | E34: Por usuario | F34: =IF(E34="Por usuario",Supuestos!$B$7,IF(E34="Por canal",Supuestos!$B$8,1)) -> 10 | G34: =D34*F34 -> 80 | H34: PyME / Empresa | J34: slite.com/learn/knowledge-base-softwares | K34: Verificado
A35: Conocimiento | B35: Notion | C35: Business | D35: 20 | E35: Por usuario | F35: =IF(E35="Por usuario",Supuestos!$B$7,IF(E35="Por canal",Supuestos!$B$8,1)) -> 10 | G35: =D35*F35 -> 200 | H35: PyME / Empresa | I35: Incluye Enterprise Search | J35: notion.com/pricing | K35: Verificado
A36: Conocimiento | B36: Document360 | C36: Professional | D36: 199 | E36: Plano | F36: =IF(E36="Por usuario",Supuestos!$B$7,IF(E36="Por canal",Supuestos!$B$8,1)) -> 1 | G36: =D36*F36 -> 199 | H36: PyME / Empresa | I36: Rango 199-499 segun uso de IA | J36: docsie.io/blog/articles/confluence-vs-document360-pricing-comparison-2026 | K36: Verificado
A37: Equipos | B37: Slack | C37: Pro | D37: 7.25 | E37: Por usuario | F37: =IF(E37="Por usuario",Supuestos!$B$7,IF(E37="Por canal",Supuestos!$B$8,1)) -> 10 | G37: =D37*F37 -> 72.5 | H37: PyME / Empresa | I37: Pago anual | J37: costbench.com/software/communication/slack | K37: Verificado
A38: Equipos | B38: Slack | C38: Business+ | D38: 12.5 | E38: Por usuario | F38: =IF(E38="Por usuario",Supuestos!$B$7,IF(E38="Por canal",Supuestos!$B$8,1)) -> 10 | G38: =D38*F38 -> 125 | H38: PyME / Empresa | J38: costbench.com/software/communication/slack | K38: Verificado
A39: Equipos | B39: Microsoft Teams | C39: Essentials | D39: 4 | E39: Por usuario | F39: =IF(E39="Por usuario",Supuestos!$B$7,IF(E39="Por canal",Supuestos!$B$8,1)) -> 10 | G39: =D39*F39 -> 40 | H39: PyME / Empresa | I39: Sube a USD 4,50 en jul-2026 | J39: getpricepulse.com/companies/slack-vs-microsoft-teams-pricing | K39: Verificado
A40: Equipos | B40: Microsoft 365 | C40: Business Basic | D40: 6 | E40: Por usuario | F40: =IF(E40="Por usuario",Supuestos!$B$7,IF(E40="Por canal",Supuestos!$B$8,1)) -> 10 | G40: =D40*F40 -> 60 | H40: PyME / Empresa | I40: Teams + Office web | J40: getpricepulse.com/companies/slack-vs-microsoft-teams-pricing | K40: Verificado
A41: Equipos | B41: Microsoft 365 | C41: Business Standard | D41: 12.5 | E41: Por usuario | F41: =IF(E41="Por usuario",Supuestos!$B$7,IF(E41="Por canal",Supuestos!$B$8,1)) -> 10 | G41: =D41*F41 -> 125 | H41: PyME / Empresa | I41: Incluye Office escritorio | J41: getpricepulse.com/companies/slack-vs-microsoft-teams-pricing | K41: Verificado
...

Sheet Modelo de Suscripcion
A1: Modelo de suscripcion sugerido
A2: Precio a la carta, planes por tamano de empresa y kits por necesidad. Todo se recalcula desde Supuestos.
A4: 1. Precio a la carta (modulo suelto)
A5: Modulo | B5: Precio sugerido (USD/mes) | C5: Mediana del mercado | D5: Posicion vs mercado
A6: Escritorio Kimos | B6: ='Mapa Competitivo'!J5 -> 116 | C6: ='Mapa Competitivo'!H5 -> 210 | D6: =IF(C6=0,0,B6/C6-1) -> -0.44761905
A7: Agentes | B7: ='Mapa Competitivo'!J6 -> 46 | C7: ='Mapa Competitivo'!H6 -> 84.495 | D7: =IF(C7=0,0,B7/C7-1) -> -0.45558909
A8: Agentes Web | B8: ='Mapa Competitivo'!J7 -> 66 | C8: ='Mapa Competitivo'!H7 -> 120 | D8: =IF(C8=0,0,B8/C8-1) -> -0.45
A9: Archivos | B9: ='Mapa Competitivo'!J8 -> 110 | C9: ='Mapa Competitivo'!H8 -> 200 | D9: =IF(C9=0,0,B9/C9-1) -> -0.45
A10: Conocimiento | B10: ='Mapa Competitivo'!J9 -> 109 | C10: ='Mapa Competitivo'!H9 -> 199 | D10: =IF(C10=0,0,B10/C10-1) -> -0.45226131
A11: Equipos | B11: ='Mapa Competitivo'!J10 -> 40 | C11: ='Mapa Competitivo'!H10 -> 72.5 | D11: =IF(C11=0,0,B11/C11-1) -> -0.44827586
A12: Kanban | B12: ='Mapa Competitivo'!J11 -> 66 | C12: ='Mapa Competitivo'!H11 -> 120 | D12: =IF(C12=0,0,B12/C12-1) -> -0.45
A13: Planificacion (Gantt) | B13: ='Mapa Competitivo'!J12 -> 55 | C13: ='Mapa Competitivo'!H12 -> 100 | D13: =IF(C13=0,0,B13/C13-1) -> -0.45
A14: Notas de Equipo | B14: ='Mapa Competitivo'!J13 -> 66 | C14: ='Mapa Competitivo'!H13 -> 120 | D14: =IF(C14=0,0,B14/C14-1) -> -0.45
A15: HTML Panel / Dashboards | B15: ='Mapa Competitivo'!J14 -> 132 | C15: ='Mapa Competitivo'!H14 -> 240 | D15: =IF(C15=0,0,B15/C15-1) -> -0.45
A16: FossFLOW (BPM) | B16: ='Mapa Competitivo'!J15 -> 55 | C16: ='Mapa Competitivo'!H15 -> 99.5 | D16: =IF(C16=0,0,B16/C16-1) -> -0.44723618
A17: Digitai (automatizacion IA) | B17: ='Mapa Competitivo'!J16 -> 34 | C17: ='Mapa Competitivo'!H16 -> 62 | D17: =IF(C17=0,0,B17/C17-1) -> -0.4516129
... A29: Integraciones | B29: ='Mapa Competitivo'!J28 -> 12 | C29: ='Mapa Competitivo'!H28 -> 21.995 | D29: =IF(C29=0,0,B29/C29-1) -> -0.45442146
A30: TOTAL suite completa a la carta | B30: =SUM(B6:B29) -> 2046 | C30: =SUM(C6:C29) -> 3719.99 | D30: =IF(C30=0,0,B30/C30-1) -> -0.44999852
A33: 2. Planes por tamano de empresa
A34: Plan / Kit | B34: Para quien es | C34: Que incluye | D34: Suma a la carta | E34: Descuento | F34: Precio mensual | G34: Por usuario | H34: Precio anual | I34: Ahorro anual del cliente
A35: Core | B35: Empresas que entran a probar la suite | C35: Plataforma base: escritorio con agentes, archivos, notas, equipos, conocimiento e integraciones | D35: =B6+B9+B14+B11+B10+B29 -> 453 | E35: 0.55 | F35: =ROUND(D35*(1-E35),0) -> 204 | G35: =ROUND(F35/Supuestos!$B$7,1) -> 20.4 | H35: =ROUND(F35*12*(1-Supuestos!$B$10),0) -> 1958 | I35: =D35*12-H35 -> 3478
A36: Starter | B36: PyMEs de 5 a 20 personas sin procesos formales | C36: Core + gestion de tareas + captura de leads | D36: =B6+B9+B14+B11+B10+B29+B12+B18 -> 546 | E36: 0.55 | F36: =ROUND(D36*(1-E36),0) -> 246 | G36: =ROUND(F36/Supuestos!$B$7,1) -> 24.6 | H36: =ROUND(F36*12*(1-Supuestos!$B$10),0) -> 2362 | I36: =D36*12-H36 -> 4190
A37: Business | B37: Empresas de 20 a 100 personas con equipo comercial | C37: Core + proyectos + CRM + marketing + dashboards + agentes IA | D37: =B6+B9+B14+B11+B10+B29+B12+B18+B13+B19+B20+B21+B15+B7 -> 1165 | E37: 0.6 | F37: =ROUND(D37*(1-E37),0) -> 466 | G37: =ROUND(F37/Supuestos!$B$7,1) -> 46.6 | H37: =ROUND(F37*12*(1-Supuestos!$B$10),0) -> 4474 | I37: =D37*12-H37 -> 9506
A38: Enterprise | B38: Empresas de 100+ personas o con procesos regulados | C38: Todos los modulos, incluidos BPM, PIM, Tienda, Cashflow, ProductLab, Eventos y Agentes Web | D38: =B6+B7+B8+B9+B10+B11+B12+B13+B14+B15+B16+B17+B18+B19+B20+B21+B22+B23+B24+B25+B26+B27+B28+B29 -> 2046 | E38: 0.62 | F38: =ROUND(D38*(1-E38),0) -> 777 | G38: =ROUND(F38/Supuestos!$B$7,1) -> 77.7 | H38: =ROUND(F38*12*(1-Supuestos!$B$10),0) -> 7459 | I38: =D38*12-H38 -> 17093
A41: 3. Kits por necesidad del cliente
A42: Plan / Kit | B42: Para quien es | C42: Que incluye | D42: Suma a la carta | E42: Descuento | F42: Precio mensual | G42: Por usuario | H42: Precio anual | I42: Ahorro anual del cliente
A43: Kit Comercial | B43: Equipos de ventas y marketing | C43: Captar, atender y cerrar: CRM + formularios + chatbot + redes + diseno | D43: =B19+B18+B8+B20+B21 -> 479 | E43: 0.45 | F43: =ROUND(D43*(1-E43),0) -> 263 | G43: =ROUND(F43/Supuestos!$B$7,1) -> 26.3 | H43: =ROUND(F43*12*(1-Supuestos!$B$10),0) -> 2525 | I43: =D43*12-H43 -> 3223
A44: Kit Operaciones | B44: PMOs, operaciones y consultoras | C44: Ejecutar y controlar: tareas + Gantt + procesos + paneles | D44: =B12+B13+B16+B15+B14 -> 374 | E44: 0.45 | F44: =ROUND(D44*(1-E44),0) -> 206 | G44: =ROUND(F44/Supuestos!$B$7,1) -> 20.6 | H44: =ROUND(F44*12*(1-Supuestos!$B$10),0) -> 1978 | I44: =D44*12-H44 -> 2510
A45: Kit Retail | B45: Retail, distribucion y marcas | C45: Vender en linea: catalogo maestro + tienda + vitrina + bot + diseno | D45: =B24+B25+B26+B8+B21 -> 472 | E45: 0.45 | F45: =ROUND(D45*(1-E45),0) -> 260 | G45: =ROUND(F45/Supuestos!$B$7,1) -> 26 | H45: =ROUND(F45*12*(1-Supuestos!$B$10),0) -> 2496 | I45: =D45*12-H45 -> 3168
A46: Kit IA | B46: Equipos tecnicos y de innovacion | C46: Automatizar con IA: escritorio + agentes + pipelines de datos + bot + base de conocimiento | D46: =B6+B7+B17+B8+B10 -> 371 | E46: 0.45 | F46: =ROUND(D46*(1-E46),0) -> 204 | G46: =ROUND(F46/Supuestos!$B$7,1) -> 20.4 | H46: =ROUND(F46*12*(1-Supuestos!$B$10),0) -> 1958 | I46: =D46*12-H46 -> 2494
A47: Kit Finanzas y Gestion | B47: Gerencia financiera | C47: Controlar la plata: flujo de caja + paneles + planificacion + documentos | D47: =B27+B15+B13+B9 -> 374 | E47: 0.45 | F47: =ROUND(D47*(1-E47),0) -> 206 | G47: =ROUND(F47/Supuestos!$B$7,1) -> 20.6 | H47: =ROUND(F47*12*(1-Supuestos!$B$10),0) -> 1978 | I47: =D47*12-H47 -> 2510
A50: 4. Chequeo de realidad: que gasta hoy el cliente sin KIMOS
A51: Necesidad | B51: Herramienta que se usa hoy | C51: Plan | D51: Costo mensual (USD)
A52: Archivos, correo y videollamadas | B52: Google Workspace | C52: Business Standard | D52: ='Detalle Competencia'!G26 -> 140
A53: Chat de equipo | B53: Slack | C53: Pro | D53: ='Detalle Competencia'!G37 -> 72.5
A54: Tareas y proyectos | B54: ClickUp | C54: Business | D54: ='Detalle Competencia'!G46 -> 120
A55: Planificacion Gantt | B55: Smartsheet | C55: Pro | D55: ='Detalle Competencia'!G51 -> 90
A56: Base de conocimiento | B56: Confluence | C56: Standard | D56: ='Detalle Competencia'!G32 -> 54.2
A57: Notas colaborativas | B57: Notion | C57: Plus | D57: ='Detalle Competencia'!G59 -> 100
A58: CRM y prospeccion | B58: Pipedrive | C58: Growth | D58: ='Detalle Competencia'!G92 -> 390
...

Sheet D1 Supuestos Demanda
A1: Estudio de demanda - supuestos del modelo
A2: Editar solo las celdas azules sobre ambar. El embudo TAM/SAM/SOM y los unit economics se recalculan.
A4: Parametro | B4: Valor | C4: Unidad | D4: Comentario
A5: Mercado SaaS global 2026 | B5: 375570 | C5: USD MM | D5: Suma de las cinco regiones
A6: Gasto en suites de gestion | B6: 0.22 | C6: % del SaaS | D6: Supuesto: participacion de suites de gestion y productividad
A7: Participacion PyME y mid-market | B7: 0.45 | C7: % de la categoria | D7: Supuesto
A8: Segmento 10-250 empleados | B8: 0.55 | C8: % del segmento | D8: Supuesto: rango que KIMOS puede atender
A9: Churn mensual | B9: 0.04 | C9: % | D9: Benchmark PyME: 3% a 7%, mediana 3,5%
A10: Margen bruto | B10: 0.75 | C10: % | D10: Castigado por el costo variable de IA
A11: CAC promedio | B11: 1200 | C11: USD | D11: Benchmark PyME autoservicio: USD 200 a 700
A12: Clientes captados al ano 3 | B12: 550 | C12: clientes | D12: Bruto acumulado, antes de churn

Sheet D2 Mercado por Region
A1: Mercado global por region - TAM y SAM
A2: Cobertura comercial e indice de precio son supuestos editables. El mercado SaaS y el CAGR son datos de fuente.
A4: Region | B4: Mercado SaaS 2026 (USD MM) | C4: % global | D4: CAGR | E4: TAM (USD MM) | F4: Cobertura KIMOS | G4: SAM (USD MM) | H4: Indice de precio | I4: Lectura | J4: Fuente | K4: Confianza
A5: Norteamerica | B5: 172680 | C5: 0.46 | D5: 0.13 | E5: =B5*'D1 Supuestos Demanda'!$B$6*'D1 Supuestos Demanda'!$B$7 -> 17095.32 | F5: 0.15 | G5: =E5*'D1 Supuestos Demanda'!$B$8*F5 -> 1410.3639 | H5: 1 | I5: EE.UU. y Canada. Mayor concentracion de proveedores e infraestructura cloud madura. Tambien donde estan todos los competidores con capital ilimitado. | J5: fortunebusinessinsights.com/software-as-a-service-saas-market-102222 | K5: Verificado
A6: Asia-Pacifico | B6: 86060 | C6: 0.229 | D6: 0.22 | E6: =B6*'D1 Supuestos Demanda'!$B$6*'D1 Supuestos Demanda'!$B$7 -> 8519.94 | F6: 0.1 | G6: =E6*'D1 Supuestos Demanda'!$B$8*F6 -> 468.5967 | H6: 0.7 | I6: Region de mayor crecimiento del mundo. Mayor varianza interna de precio: 40 puntos entre Japon/Australia y el sudeste asiatico emergente. | J6: precedenceresearch.com/software-as-a-service-market | K6: Verificado
A7: Europa | B7: 70810 | C7: 0.189 | D7: 0.12 | E7: =B7*'D1 Supuestos Demanda'!$B$6*'D1 Supuestos Demanda'!$B$7 -> 7010.19 | F7: 0.2 | G7: =E7*'D1 Supuestos Demanda'!$B$8*F7 -> 771.1209 | H7: 0.95 | I7: Mercado maduro con alta exigencia de cumplimiento (GDPR, residencia de datos). Los nordicos pagan 8-18% de premium sobre el baseline de EE.UU. | J7: fortunebusinessinsights.com/software-as-a-service-saas-market-102222 | K7: Verificado
A8: America Latina | B8: 21000 | C8: 0.056 | D8: 0.148 | E8: =B8*'D1 Supuestos Demanda'!$B$6*'D1 Supuestos Demanda'!$B$7 -> 2079 | F8: 0.6 | G8: =E8*'D1 Supuestos Demanda'!$B$8*F8 -> 686.07 | H8: 0.6 | I8: USD 21.000 MM en 2025, proyectado a USD 45.000 MM en 2030. Brasil concentra el 60% de las ~17.000 empresas SaaS de la region. | J8: informesdeexpertos.com/informes/mercado-latinoamericano-de-software-como-servicio-saas | K8: Verificado
A9: Medio Oriente y Africa | B9: 25020 | C9: 0.066 | D9: 0.16 | E9: =B9*'D1 Supuestos Demanda'!$B$6*'D1 Supuestos Demanda'!$B$7 -> 2476.98 | F9: 0.05 | G9: =E9*'D1 Supuestos Demanda'!$B$8*F9 -> 68.11695 | H9: 0.55 | I9: Residual del total global. Mercado incipiente, alta dependencia de proveedores globales. | J9: Calculo residual sobre el total global de USD 375.570 MM | K9: Estimado
A10: TOTAL GLOBAL | B10: =SUM(B5:B9) -> 375570 | E10: =SUM(E5:E9) -> 37181.43 | G10: =SUM(G5:G9) -> 3404.2685

Sheet D2b Mercados por Pais
A1: Los 30 mercados, pais por pais
A2: El peso normaliza cada pais dentro de su region para que la suma de exactamente el total regional. La columna 'publicado' muestra la cifra 2026 de fuente cuando existe: la diferencia es el desacuerdo entre estudios y se deja a la vista.
A4: Pais o mercado | B4: Region | C4: Idioma | D4: Prioridad | E4: Cobertura | F4: Peso en la region | G4: Mercado SaaS 2026 (USD MM) | H4: Publicado (USD MM) | I4: Desvio | J4: TAM (USD MM) | K4: SAM (USD MM) | L4: Indice de precio | M4: Empresas | N4: Contexto | O4: Confianza
A5: Estados Unidos | B5: Norteamerica | C5: Ingles | D5: Expansion | E5: 0.2 | F5: 0.7935 | G5: =F5*'D2 Mercado por Region'!B5 -> 137021.58 | H5: 141060 | I5: =G5/H5-1 -> -0.028629094 | J5: =G5*'D1 Supuestos Demanda'!$B$6*'D1 Supuestos Demanda'!$B$7 -> 13565.136 | K5: =J5*'D1 Supuestos Demanda'!$B$8*E5 -> 1492.165 | L5: 1 | M5: 36200000 | N5: USD 141.060 MM en 2026, el 37,5% del mercado mundial. 36,2 millones de pequenas empresas, el 99,9% del total. | O5: Verificado
A6: Canada | B6: Norteamerica | C6: Ingles | D6: Expansion | E6: 0.2 | F6: 0.2065 | G6: =F6*'D2 Mercado por Region'!B5 -> 35658.42 | H6: 36700 | I6: =G6/H6-1 -> -0.028380926 | J6: =G6*'D1 Supuestos Demanda'!$B$6*'D1 Supuestos Demanda'!$B$7 -> 3530.1836 | K6: =J6*'D1 Supuestos Demanda'!$B$8*E6 -> 388.32019 | L6: 0.95 | M6: s/d | N6: USD 36.700 MM: el 16% del gasto SaaS norteamericano. Crece al 12,6% anual hasta 2030. | O6: Verificado
A7: Alemania | B7: Europa | C7: Aleman | D7: Oportunista | E7: 0.08 | F7: 0.2092 | G7: =F7*'D2 Mercado por Region'!B7 -> 14813.452 | H7: 14810 | I7: =G7/H7-1 -> 0.00023308575 | J7: =G7*'D1 Supuestos Demanda'!$B$6*'D1 Supuestos Demanda'!$B$7 -> 1466.5317 | K7: =J7*'D1 Supuestos Demanda'!$B$8*E7 -> 64.527397 | L7: 0.98 | M7: 3200000 | N7: El mayor mercado SaaS de Europa. 3,2 millones de empresas activas. | O7: Verificado
A8: Francia | B8: Europa | C8: Frances | D8: Oportunista | E8: 0.08 | F8: 0.1863 | G8: =F8*'D2 Mercado por Region'!B7 -> 13191.903 | H8: 13190 | I8: =G8/H8-1 -> 0.00014427597 | J8: =G8*'D1 Supuestos Demanda'!$B$6*'D1 Supuestos Demanda'!$B$7 -> 1305.9984 | K8: =J8*'D1 Supuestos Demanda'!$B$8*E8 -> 57.463929 | L8: 0.95 | M8: 5300000 | N8: 5,3 millones de empresas activas, la mayor poblacion empresarial de la UE. | O8: Verificado
A9: Reino Unido | B9: Europa | C9: Ingles | D9: Expansion | E9: 0.2 | F9: 0.1826 | G9: =F9*'D2 Mercado por Region'!B7 -> 12929.906 | H9: 12930 | I9: =G9/H9-1 -> -7.2699149e-06 | J9: =G9*'D1 Supuestos Demanda'!$B$6*'D1 Supuestos Demanda'!$B$7 -> 1280.0607 | K9: =J9*'D1 Supuestos Demanda'!$B$8*E9 -> 140.80668 | L9: 0.98 | M9: s/d | N9: Puerta de entrada natural a Europa por idioma y practica comercial. | O9: Verificado
A10: Italia | B10: Europa | C10: Italiano | D10: Oportunista | E10: 0.08 | F10: 0.0833 | G10: =F10*'D2 Mercado por Region'!B7 -> 5898.473 | H10: s/d | I10: - | J10: =G10*'D1 Supuestos Demanda'!$B$6*'D1 Supuestos Demanda'!$B$7 -> 583.94883 | K10: =J10*'D1 Supuestos Demanda'!$B$8*E10 -> 25.693748 | L10: 0.85 | M10: 4600000 | N10: 4,6 millones de empresas activas. Mercado cloud de USD 14.300 MM en 2025 creciendo al 16,4%. | O10: Estimado
A11: Espana | B11: Europa | C11: Espanol | D11: Prioritario | E11: 0.6 | F11: 0.0621 | G11: =F11*'D2 Mercado por Region'!B7 -> 4397.301 | H11: s/d | I11: - | J11: =G11*'D1 Supuestos Demanda'!$B$6*'D1 Supuestos Demanda'!$B$7 -> 435.3328 | K11: =J11*'D1 Supuestos Demanda'!$B$8*E11 -> 143.65982 | L11: 0.82 | M11: 3500000 | N11: 3,5 millones de empresas activas. Mismo idioma: es el puente entre LATAM y Europa. | O11: Estimado
A12: Nordicos | B12: Europa | C12: Ingles | D12: Oportunista | E12: 0.08 | F12: 0.065 | G12: =F12*'D2 Mercado por Region'!B7 -> 4602.65 | H12: s/d | I12: - | J12: =G12*'D1 Supuestos Demanda'!$B$6*'D1 Supuestos Demanda'!$B$7 -> 455.66235 | K12: =J12*'D1 Supuestos Demanda'!$B$8*E12 -> 20.049143 | L12: 1.05 | M12: s/d | N12: Suecia, Dinamarca, Noruega y Finlandia. Pagan entre 8% y 18% de premium sobre la lista de EE.UU. | O12: Estimado
A13: Paises Bajos | B13: Europa | C13: Neerlandes | D13: Oportunista | E13: 0.08 | F13: 0.0466 | G13: =F13*'D2 Mercado por Region'!B7 -> 3299.746 | H13: s/d | I13: - | J13: =G13*'D1 Supuestos Demanda'!$B$6*'D1 Supuestos Demanda'!$B$7 -> 326.67485 | K13: =J13*'D1 Supuestos Demanda'!$B$8*E13 -> 14.373694 | L13: 0.98 | M13: s/d | N13: Alta digitalizacion y operacion comercial en ingles. | O13: Estimado
A14: Polonia | B14: Europa | C14: Polaco | D14: No perseguir | E14: 0.01 | F14: 0.0311 | G14: =F14*'D2 Mercado por Region'!B7 -> 2202.191 | H14: s/d | I14: - | J14: =G14*'D1 Supuestos Demanda'!$B$6*'D1 Supuestos Demanda'!$B$7 -> 218.01691 | K14: =J14*'D1 Supuestos Demanda'!$B$8*E14 -> 1.199093 | L14: 0.62 | M14: s/d | N14: Crece rapido pero con menor poder adquisitivo y competencia local fuerte. | O14: Estimado
A15: Resto de Europa | B15: Europa | C15: Varios | D15: No perseguir | E15: 0.01 | F15: 0.1338 | G15: =F15*'D2 Mercado por Region'!B7 -> 9474.378 | H15: s/d | I15: - | J15: =G15*'D1 Supuestos Demanda'!$B$6*'D1 Supuestos Demanda'!$B$7 -> 937.96342 | K15: =J15*'D1 Supuestos Demanda'!$B$8*E15 -> 5.1587988 | L15: 0.75 | M15: s/d | N15: Agregado del resto del continente. Total de PyMEs en la UE: 34 millones. | O15: Derivado
A16: China | B16: Asia-Pacifico | C16: Chino | D16: No perseguir | E16: 0.01 | F16: 0.2259 | G16: =F16*'D2 Mercado por Region'!B6 -> 19440.954 | H16: 19440 | I16: =G16/H16-1 -> 4.9074074e-05 | J16: =G16*'D1 Supuestos Demanda'!$B$6*'D1 Supuestos Demanda'!$B$7 -> 1924.6544 | K16: =J16*'D1 Supuestos Demanda'!$B$8*E16 -> 10.585599 | L16: 0.55 | M16: s/d | N16: El mayor mercado de la region. Ecosistema cerrado y competencia local dominante. | O16: Verificado
A17: India | B17: Asia-Pacifico | C17: Ingles | D17: No perseguir | E17: 0.01 | F17: 0.2004 | G17: =F17*'D2 Mercado por Region'!B6 -> 17246.424 | H17: 17250 | I17: =G17/H17-1 -> -0.00020730435 | J17: =G17*'D1 Supuestos Demanda'!$B$6*'D1 Supuestos Demanda'!$B$7 -> 1707.396 | K17: =J17*'D1 Supuestos Demanda'!$B$8*E17 -> 9.3906779 | L17: 0.35 | M17: s/d | N17: Proyectado a USD 58.400 MM en 2033 creciendo al 16,9% anual: el de mayor crecimiento del mundo, y tambien el mas sensible al precio. | O17: Verificado
A18: Japon | B18: Asia-Pacifico | C18: Japones | D18: No perseguir | E18: 0.01 | F18: 0.1981 | G18: =F18*'D2 Mercado por Region'!B6 -> 17048.486 | H18: 17050 | I18: =G18/H18-1 -> -8.8797654e-05 | J18: =G18*'D1 Supuestos Demanda'!$B$6*'D1 Supuestos Demanda'!$B$7 -> 1687.8001 | K18: =J18*'D1 Supuestos Demanda'!$B$8*E18 -> 9.2829006 | L18: 0.85 | M18: 3500000 | N18: 3,5 millones de MiPymes, el 99,7% de las empresas. Exige localizacion profunda y ciclos largos. | O18: Verificado
A19: Australia | B19: Asia-Pacifico | C19: Ingles | D19: Oportunista | E19: 0.08 | F19: 0.1604 | G19: =F19*'D2 Mercado por Region'!B6 -> 13804.024 | H19: 13800 | I19: =G19/H19-1 -> 0.0002915942 | J19: =G19*'D1 Supuestos Demanda'!$B$6*'D1 Supuestos Demanda'!$B$7 -> 1366.5984 | K19: =J19*'D1 Supuestos Demanda'!$B$8*E19 -> 60.130329 | L19: 0.98 | M19: s/d | N19: USD 13.800 MM estimados para 2026. El 2,6% del mercado mundial y el mercado mas accesible de la region por idioma. | O19: Verificado
A20: Corea del Sur | B20: Asia-Pacifico | C20: Coreano | D20: No perseguir | E20: 0.01 | F20: 0.0755 | G20: =F20*'D2 Mercado por Region'!B6 -> 6497.53 | H20: s/d | I20: - | J20: =G20*'D1 Supuestos Demanda'!$B$6*'D1 Supuestos Demanda'!$B$7 -> 643.25547 | K20: =J20*'D1 Supuestos Demanda'!$B$8*E20 -> 3.5379051 | L20: 0.8 | M20: s/d | N20: Crece al 9,4% anual. Alta digitalizacion pero fuerte preferencia por proveedores locales. | O20: Estimado
A21: Singapur | B21: Asia-Pacifico | C21: Ingles | D21: Oportunista | E21: 0.08 | F21: 0.0349 | G21: =F21*'D2 Mercado por Region'!B6 -> 3003.494 | H21: s/d | I21: - | J21: =G21*'D1 Supuestos Demanda'!$B$6*'D1 Supuestos Demanda'!$B$7 -> 297.34591 | K21: =J21*'D1 Supuestos Demanda'!$B$8*E21 -> 13.08322 | L21: 0.95 | M21: s/d | N21: Pequeno pero de alto ticket y en ingles. Buena cabecera de playa regional. | O21: Estimado
A22: Resto de Asia-Pacifico | B22: Asia-Pacifico | C22: Varios | D22: No perseguir | E22: 0.01 | F22: 0.1048 | G22: =F22*'D2 Mercado por Region'!B6 -> 9019.088 | H22: s/d | I22: - | J22: =G22*'D1 Supuestos Demanda'!$B$6*'D1 Supuestos Demanda'!$B$7 -> 892.88971 | K22: =J22*'D1 Supuestos Demanda'!$B$8*E22 -> 4.9108934 | L22: 0.5 | M22: s/d | N22: Sudeste asiatico emergente. Hasta 40 puntos de precio por debajo de Japon y Australia. | O22: Derivado
A23: Brasil | B23: America Latina | C23: Portugues | D23: Expansion | E23: 0.2 | F23: 0.5513 | G23: =F23*'D2 Mercado por Region'!B8 -> 11577.3 | H23: 11578 | I23: =G23/H23-1 -> -6.0459492e-05 | J23: =G23*'D1 Supuestos Demanda'!$B$6*'D1 Supuestos Demanda'!$B$7 -> 1146.1527 | K23: =J23*'D1 Supuestos Demanda'!$B$8*E23 -> 126.0768 | L23: 0.55 | M23: s/d | N23: USD 9.216 MM en 2024 creciendo al 12,1% anual. Concentra el 60% de las ~17.000 empresas SaaS de la region. | O23: Verificado
A24: Mexico | B24: America Latina | C24: Espanol | D24: Prioritario | E24: 0.6 | F24: 0.17 | G24: =F24*'D2 Mercado por Region'!B8 -> 3570 | H24: 3570 | I24: =G24/H24-1 -> 0 | J24: =G24*'D1 Supuestos Demanda'!$B$6*'D1 Supuestos Demanda'!$B$7 -> 353.43 | K24: =J24*'D1 Supuestos Demanda'!$B$8*E24 -> 116.6319 | L24: 0.6 | M24: 6000000 | N24: El 17% del mercado SaaS latinoamericano. 6 millones de unidades economicas; las pymes dan 7 de cada 10 empleos. | O24: Verificado
A25: Argentina | B25: America Latina | C25: Espanol | D25: Prioritario | E25: 0.6 | F25: 0.0619 | G25: =F25*'D2 Mercado por Region'!B8 -> 1299.9 | H25: s/d | I25: - | J25: =G25*'D1 Supuestos Demanda'!$B$6*'D1 Supuestos Demanda'!$B$7 -> 128.6901 | K25: =J25*'D1 Supuestos Demanda'!$B$8*E25 -> 42.467733 | L25: 0.45 | M25: s/d | N25: Las pymes son el 99,4% de las empresas y emplean al 64% de los asalariados. El 41,6% ya usa alguna herramienta de IA. | O25: Estimado
A26: Colombia | B26: America Latina | C26: Espanol | D26: Prioritario | E26: 0.6 | F26: 0.0548 | G26: =F26*'D2 Mercado por Region'!B8 -> 1150.8 | H26: s/d | I26: - | J26: =G26*'D1 Supuestos Demanda'!$B$6*'D1 Supuestos Demanda'!$B$7 -> 113.9292 | K26: =J26*'D1 Supuestos Demanda'!$B$8*E26 -> 37.596636 | L26: 0.5 | M26: s/d | N26: Uno de los paises mas emprendedores de la region junto con Mexico y Peru. | O26: Estimado
A27: Chile | B27: America Latina | C27: Espanol | D27: Prioritario | E27: 0.6 | F27: 0.0548 | G27: =F27*'D2 Mercado por Region'!B8 -> 1150.8 | H27: s/d | I27: - | J27: =G27*'D1 Supuestos Demanda'!$B$6*'D1 Supuestos Demanda'!$B$7 -> 113.9292 | K27: =J27*'D1 Supuestos Demanda'!$B$8*E27 -> 37.596636 | L27: 0.62 | M27: 1194430 | N27: Mercado base de KIMOS. 1,19 millones de MiPymes formales y el mayor poder adquisitivo de la region. | O27: Estimado
A28: Peru | B28: America Latina | C28: Espanol | D28: Prioritario | E28: 0.6 | F28: 0.0286 | G28: =F28*'D2 Mercado por Region'!B8 -> 600.6 | H28: s/d | I28: - | J28: =G28*'D1 Supuestos Demanda'!$B$6*'D1 Supuestos Demanda'!$B$7 -> 59.4594 | K28: =J28*'D1 Supuestos Demanda'!$B$8*E28 -> 19.621602 | L28: 0.5 | M28: 2100000 | N28: Mas de 2,1 millones de MiPymes formales. | O28: Estimado
A29: Resto de America Latina | B29: America Latina | C29: Espanol | D29: Prioritario | E29: 0.6 | F29: 0.0786 | G29: =F29*'D2 Mercado por Region'!B8 -> 1650.6 | H29: s/d | I29: - | J29: =G29*'D1 Supuestos Demanda'!$B$6*'D1 Supuestos Demanda'!$B$7 -> 163.4094 | K29: =J29*'D1 Supuestos Demanda'!$B$8*E29 -> 53.925102 | L29: 0.5 | M29: s/d | N29: Centroamerica, Caribe hispano, Ecuador, Uruguay, Bolivia y Paraguay. | O29: Derivado
A30: Arabia Saudita | B30: Medio Oriente y Africa | C30: Arabe | D30: No perseguir | E30: 0.01 | F30: 0.18 | G30: =F30*'D2 Mercado por Region'!B9 -> 4503.6 | H30: s/d | I30: - | J30: =G30*'D1 Supuestos Demanda'!$B$6*'D1 Supuestos Demanda'!$B$7 -> 445.8564 | K30: =J30*'D1 Supuestos Demanda'!$B$8*E30 -> 2.4522102 | L30: 0.85 | M30: s/d | N30: Fuerte inversion estatal en digitalizacion. | O30: Estimado
A31: Emiratos Arabes Unidos | B31: Medio Oriente y Africa | C31: Ingles | D31: Oportunista | E31: 0.08 | F31: 0.16 | G31: =F31*'D2 Mercado por Region'!B9 -> 4003.2 | H31: s/d | I31: - | J31: =G31*'D1 Supuestos Demanda'!$B$6*'D1 Supuestos Demanda'!$B$7 -> 396.3168 | K31: =J31*'D1 Supuestos Demanda'!$B$8*E31 -> 17.437939 | L31: 0.9 | M31: s/d | N31: Hub regional, alto poder adquisitivo y operacion en ingles. | O31: Estimado
A32: Israel | B32: Medio Oriente y Africa | C32: Ingles | D32: Oportunista | E32: 0.08 | F32: 0.12 | G32: =F32*'D2 Mercado por Region'!B9 -> 3002.4 | H32: s/d | I32: - | J32: =G32*'D1 Supuestos Demanda'!$B$6*'D1 Supuestos Demanda'!$B$7 -> 297.2376 | K32: =J32*'D1 Supuestos Demanda'!$B$8*E32 -> 13.078454 | L32: 0.95 | M32: s/d | N32: Alta densidad tecnologica y tambien altisima competencia local. | O32: Estimado
A33: Sudafrica | B33: Medio Oriente y Africa | C33: Ingles | D33: No perseguir | E33: 0.01 | F33: 0.1 | G33: =F33*'D2 Mercado por Region'!B9 -> 2502 | H33: s/d | I33: - | J33: =G33*'D1 Supuestos Demanda'!$B$6*'D1 Supuestos Demanda'!$B$7 -> 247.698 | K33: =J33*'D1 Supuestos Demanda'!$B$8*E33 -> 1.362339 | L33: 0.5 | M33: s/d | N33: Principal mercado del africa subsahariana. | O33: Estimado
A34: Resto de Medio Oriente y Africa | B34: Medio Oriente y Africa | C34: Varios | D34: No perseguir | E34: 0.01 | F34: 0.44 | G34: =F34*'D2 Mercado por Region'!B9 -> 11008.8 | H34: s/d | I34: - | J34: =G34*'D1 Supuestos Demanda'!$B$6*'D1 Supuestos Demanda'!$B$7 -> 1089.8712 | K34: =J34*'D1 Supuestos Demanda'!$B$8*E34 -> 5.9942916 | L34: 0.4 | M34: s/d | N34: Agregado del resto de la region. | O34: Derivado
A35: TOTAL | G35: =SUM(G5:G34) -> 375570 | J35: =SUM(J5:J34) -> 37181.43 | K35: =SUM(K5:K34) -> 2938.5807
A37: El SAM de esta hoja usa la cobertura por prioridad comercial de cada pais, mas fina que la cobertura por region de la hoja D2. Por eso ambos totales difieren.

Sheet D3 Unit Economics
A1: Economia por cliente y proyeccion a 3 anos
A2: La base neta descuenta el churn mes a mes. Sin ese descuento el churn no afectaria el ARR, que seria falso.
A4: Mix de planes y ARPU
A5: Plan | B5: Peso en el mix | C5: Precio mensual | D5: Aporte al ARPU
A6: Starter | B6: 0.6 | C6: ='Modelo de Suscripcion'!F36 -> 246 | D6: =B6*C6 -> 147.6
A7: Business | B7: 0.3 | C7: ='Modelo de Suscripcion'!F37 -> 466 | D7: =B7*C7 -> 139.8
A8: Enterprise | B8: 0.1 | C8: ='Modelo de Suscripcion'!F38 -> 777 | D8: =B8*C8 -> 77.7
A9: ARPU mensual base | D9: =SUM(D6:D8) -> 365.1
A11: Mix regional del ano 3 y ARPU ponderado
A12: Region | B12: Peso en el mix | C12: Indice de precio | D12: ARPU anual de la region | E12: Aporte ponderado
A13: America Latina | B13: 0.55 | C13: ='D2 Mercado por Region'!H8 -> 0.6 | D13: =$D$9*12*C13 -> 2628.72 | E13: =B13*D13 -> 1445.796
A14: Europa | B14: 0.18 | C14: ='D2 Mercado por Region'!H7 -> 0.95 | D14: =$D$9*12*C14 -> 4162.14 | E14: =B14*D14 -> 749.1852
A15: Norteamerica | B15: 0.15 | C15: ='D2 Mercado por Region'!H5 -> 1 | D15: =$D$9*12*C15 -> 4381.2 | E15: =B15*D15 -> 657.18
A16: Asia-Pacifico | B16: 0.1 | C16: ='D2 Mercado por Region'!H6 -> 0.7 | D16: =$D$9*12*C16 -> 3066.84 | E16: =B16*D16 -> 306.684
A17: Medio Oriente y Africa | B17: 0.02 | C17: ='D2 Mercado por Region'!H9 -> 0.55 | D17: =$D$9*12*C17 -> 2409.66 | E17: =B17*D17 -> 48.1932
A18: ARPU anual ponderado | E18: =SUM(E13:E17) -> 3207.0384
A20: Proyeccion a 3 anos por cohorte de captacion
A21: Cada cohorte se capta repartida en 12 meses y se le aplica supervivencia (1-churn)^meses. Sin esto el churn no afectaria el ARR.
A22: Cohorte | B22: Clientes nuevos en el ano | C22: Vivos al cierre ano 1 | D22: Vivos al cierre ano 2 | E22: Vivos al cierre ano 3
